Internal Server Error: /admin/planes/planning/
Traceback (most recent call last):
  File "e:\12\guz2\.env\lib\site-packages\django\contrib\sessions\backends\base.py", line 199, in _get_session
    return self._session_cache
AttributeError: 'SessionStore' object has no attribute '_session_cache'

During handling of the above exception, another exception occurred:

Traceback (most recent call last):
  File "e:\12\guz2\.env\lib\site-packages\django\core\handlers\exception.py", line 34, in inner
    response = get_response(request)
  File "e:\12\guz2\.env\lib\site-packages\django\core\handlers\base.py", line 115, in _get_response
    response = self.process_exception_by_middleware(e, request)
  File "e:\12\guz2\.env\lib\site-packages\django\core\handlers\base.py", line 113, in _get_response
    response = wrapped_callback(request, *callback_args, **callback_kwargs)
  File "e:\12\guz2\.env\lib\site-packages\django\contrib\admin\options.py", line 607, in wrapper
    return self.admin_site.admin_view(view)(*args, **kwargs)
  File "e:\12\guz2\.env\lib\site-packages\django\utils\decorators.py", line 130, in _wrapped_view
    response = view_func(request, *args, **kwargs)
  File "e:\12\guz2\.env\lib\site-packages\django\views\decorators\cache.py", line 44, in _wrapped_view_func
    response = view_func(request, *args, **kwargs)
  File "e:\12\guz2\.env\lib\site-packages\django\contrib\admin\sites.py", line 220, in inner
    if not self.has_permission(request):
  File "e:\12\guz2\.env\lib\site-packages\django\contrib\admin\sites.py", line 194, in has_permission
    return request.user.is_active and request.user.is_staff
  File "e:\12\guz2\.env\lib\site-packages\django\utils\functional.py", line 224, in inner
    self._setup()
  File "e:\12\guz2\.env\lib\site-packages\django\utils\functional.py", line 360, in _setup
    self._wrapped = self._setupfunc()
  File "e:\12\guz2\.env\lib\site-packages\django\contrib\auth\middleware.py", line 24, in <lambda>
    request.user = SimpleLazyObject(lambda: get_user(request))
  File "e:\12\guz2\.env\lib\site-packages\django\contrib\auth\middleware.py", line 12, in get_user
    request._cached_user = auth.get_user(request)
  File "e:\12\guz2\.env\lib\site-packages\django\contrib\auth\__init__.py", line 173, in get_user
    user_id = _get_user_session_key(request)
  File "e:\12\guz2\.env\lib\site-packages\django\contrib\auth\__init__.py", line 58, in _get_user_session_key
    return get_user_model()._meta.pk.to_python(request.session[SESSION_KEY])
  File "e:\12\guz2\.env\lib\site-packages\django\contrib\sessions\backends\base.py", line 64, in __getitem__
    return self._session[key]
  File "e:\12\guz2\.env\lib\site-packages\django\contrib\sessions\backends\base.py", line 204, in _get_session
    self._session_cache = self.load()
  File "e:\12\guz2\.env\lib\site-packages\django\contrib\sessions\backends\db.py", line 43, in load
    s = self._get_session_from_db()
  File "e:\12\guz2\.env\lib\site-packages\django\contrib\sessions\backends\db.py", line 34, in _get_session_from_db
    expire_date__gt=timezone.now()
  File "e:\12\guz2\.env\lib\site-packages\django\db\models\manager.py", line 82, in manager_method
    return getattr(self.get_queryset(), name)(*args, **kwargs)
  File "e:\12\guz2\.env\lib\site-packages\django\db\models\query.py", line 411, in get
    num = len(clone)
  File "e:\12\guz2\.env\lib\site-packages\django\db\models\query.py", line 258, in __len__
    self._fetch_all()
  File "e:\12\guz2\.env\lib\site-packages\django\db\models\query.py", line 1261, in _fetch_all
    self._result_cache = list(self._iterable_class(self))
  File "e:\12\guz2\.env\lib\site-packages\django\db\models\query.py", line 57, in __iter__
    results = compiler.execute_sql(chunked_fetch=self.chunked_fetch, chunk_size=self.chunk_size)
  File "e:\12\guz2\.env\lib\site-packages\django\db\models\sql\compiler.py", line 1138, in execute_sql
    sql, params = self.as_sql()
  File "e:\12\guz2\.env\lib\site-packages\django\db\models\sql\compiler.py", line 490, in as_sql
    extra_select, order_by, group_by = self.pre_sql_setup()
  File "e:\12\guz2\.env\lib\site-packages\django\db\models\sql\compiler.py", line 51, in pre_sql_setup
    self.setup_query()
  File "e:\12\guz2\.env\lib\site-packages\django\db\models\sql\compiler.py", line 42, in setup_query
    self.select, self.klass_info, self.annotation_col_map = self.get_select()
  File "e:\12\guz2\.env\lib\site-packages\django\db\models\sql\compiler.py", line 257, in get_select
    sql, params = self.compile(col)
  File "e:\12\guz2\.env\lib\site-packages\django\db\models\sql\compiler.py", line 422, in compile
    sql, params = node.as_sql(self, self.connection)
  File "e:\12\guz2\.env\lib\site-packages\django\db\models\expressions.py", line 770, in as_sql
    return "%s.%s" % (qn(self.alias), qn(self.target.column)), []
  File "e:\12\guz2\.env\lib\site-packages\django\db\models\sql\compiler.py", line 413, in quote_name_unless_alias
    r = self.connection.ops.quote_name(name)
  File "e:\12\guz2\.env\lib\site-packages\django\db\backends\dummy\base.py", line 20, in complain
    raise ImproperlyConfigured("settings.DATABASES is improperly configured. "
django.core.exceptions.ImproperlyConfigured: settings.DATABASES is improperly configured. Please supply the ENGINE value. Check settings documentation for more details.
Not Found: /planning/
Internal Server Error: /plane/
Traceback (most recent call last):
  File "e:\12\guz2\.env\lib\site-packages\django\core\handlers\exception.py", line 34, in inner
    response = get_response(request)
  File "e:\12\guz2\.env\lib\site-packages\django\core\handlers\base.py", line 115, in _get_response
    response = self.process_exception_by_middleware(e, request)
  File "e:\12\guz2\.env\lib\site-packages\django\core\handlers\base.py", line 113, in _get_response
    response = wrapped_callback(request, *callback_args, **callback_kwargs)
  File "E:\12\guz2\GAZ\planes\views.py", line 179, in plane
    for item in finance_costs:
  File "e:\12\guz2\.env\lib\site-packages\django\db\models\query.py", line 276, in __iter__
    self._fetch_all()
  File "e:\12\guz2\.env\lib\site-packages\django\db\models\query.py", line 1261, in _fetch_all
    self._result_cache = list(self._iterable_class(self))
  File "e:\12\guz2\.env\lib\site-packages\django\db\models\query.py", line 57, in __iter__
    results = compiler.execute_sql(chunked_fetch=self.chunked_fetch, chunk_size=self.chunk_size)
  File "e:\12\guz2\.env\lib\site-packages\django\db\models\sql\compiler.py", line 1138, in execute_sql
    sql, params = self.as_sql()
  File "e:\12\guz2\.env\lib\site-packages\django\db\models\sql\compiler.py", line 490, in as_sql
    extra_select, order_by, group_by = self.pre_sql_setup()
  File "e:\12\guz2\.env\lib\site-packages\django\db\models\sql\compiler.py", line 51, in pre_sql_setup
    self.setup_query()
  File "e:\12\guz2\.env\lib\site-packages\django\db\models\sql\compiler.py", line 42, in setup_query
    self.select, self.klass_info, self.annotation_col_map = self.get_select()
  File "e:\12\guz2\.env\lib\site-packages\django\db\models\sql\compiler.py", line 257, in get_select
    sql, params = self.compile(col)
  File "e:\12\guz2\.env\lib\site-packages\django\db\models\sql\compiler.py", line 422, in compile
    sql, params = node.as_sql(self, self.connection)
  File "e:\12\guz2\.env\lib\site-packages\django\db\models\expressions.py", line 770, in as_sql
    return "%s.%s" % (qn(self.alias), qn(self.target.column)), []
  File "e:\12\guz2\.env\lib\site-packages\django\db\models\sql\compiler.py", line 413, in quote_name_unless_alias
    r = self.connection.ops.quote_name(name)
  File "e:\12\guz2\.env\lib\site-packages\django\db\backends\dummy\base.py", line 20, in complain
    raise ImproperlyConfigured("settings.DATABASES is improperly configured. "
django.core.exceptions.ImproperlyConfigured: settings.DATABASES is improperly configured. Please supply the ENGINE value. Check settings documentation for more details.
Not Found: /favicon.ico
Bad Request: /
Bad Request: /favicon.ico
Not Found: /
Not Found: /favicon.ico
Not Found: /favicon.ico
Not Found: /favicon.ico
